<?xml version="1.0" ?>
<!-- =================================================================================== -->
<!-- |    This document was autogenerated by xacro from xacro/robot.xacro              | -->
<!-- |    EDITING THIS FILE BY HAND IS NOT RECOMMENDED                                 | -->
<!-- =================================================================================== -->
<!-- Name your robot here -->
<robot name="robot_urdf">
  <link name="base_link">
    <inertial>
      <origin rpy="0 0 0" xyz="0.033945 0.00011949 0.23682"/>
      <mass value="21.354"/>
      <inertia ixx="0.49496" ixy="-0.00077943" ixz="0.11652" iyy="1.7969" iyz="3.3785E-05" izz="2.1422"/>
    </inertial>
    <visual>
      <origin rpy="0 0 0" xyz="0 0 0"/>
      <geometry>
        <mesh filename="package://robot_urdf/meshes/base_link.STL"/>
      </geometry>
      <material name="">
        <color rgba="0.79216 0.81961 0.93333 1"/>
      </material>
    </visual>
    <collision>
      <origin rpy="0 0 0" xyz="0 0 0"/>
      <geometry>
        <mesh filename="package://robot_urdf/meshes/base_link.STL"/>
      </geometry>
    </collision>
  </link>
  <link name="support_left">
    <inertial>
      <origin rpy="0 0 0" xyz="-1.6376E-15 -0.00017575 -0.095491"/>
      <mass value="0.51157"/>
      <inertia ixx="0.0021825" ixy="5.816E-18" ixz="1.9269E-18" iyy="0.0015444" iyz="-7.676E-06" izz="0.0011341"/>
    </inertial>
    <visual>
      <origin rpy="0 0 0" xyz="0 0 0"/>
      <geometry>
        <mesh filename="package://robot_urdf/meshes/support_left.STL"/>
      </geometry>
      <material name="">
        <color rgba="0.89804 0.91765 0.92941 1"/>
      </material>
    </visual>
    <collision>
      <origin rpy="0 0 0" xyz="0 0 0"/>
      <geometry>
        <mesh filename="package://robot_urdf/meshes/support_left.STL"/>
      </geometry>
    </collision>
  </link>
  <joint name="j_support_left" type="revolute">
    <origin rpy="0 0 0" xyz="0.2474 0.15113 0.23622"/>
    <parent link="base_link"/>
    <child link="support_left"/>
    <axis xyz="0 0 1"/>
    <limit effort="10" lower="-1.0472" upper="1.0472" velocity="100"/>
  </joint>
  <link name="front_left_wheel">
    <inertial>
      <origin rpy="0 0 0" xyz="1.3878E-16 -0.027268 -2.7756E-17"/>
      <mass value="0.73792"/>
      <inertia ixx="0.0027981" ixy="-1.7241E-17" ixz="-2.1031E-18" iyy="0.0051346" iyz="1.7405E-18" izz="0.0027981"/>
    </inertial>
    <visual>
      <origin rpy="0 0 0" xyz="0 0 0"/>
      <geometry>
        <mesh filename="package://robot_urdf/meshes/front_left_wheel.STL"/>
      </geometry>
      <material name="">
        <color rgba="0.79216 0.81961 0.93333 1"/>
      </material>
    </visual>
    <collision>
      <origin rpy="0 0 0" xyz="0 0 0"/>
      <geometry>
        <mesh filename="package://robot_urdf/meshes/front_left_wheel.STL"/>
      </geometry>
    </collision>
  </link>
  <joint name="j_front_left_wheel" type="continuous">
    <origin rpy="0 0 0" xyz="0 0.03048 -0.13462"/>
    <parent link="support_left"/>
    <child link="front_left_wheel"/>
    <axis xyz="0 -1 0"/>
    <limit effort="30" velocity="100"/>
  </joint>
  <link name="support_right">
    <inertial>
      <origin rpy="0 0 0" xyz="1.1102E-16 -0.00017575 -0.095491"/>
      <mass value="0.51157"/>
      <inertia ixx="0.0021825" ixy="-3.401E-18" ixz="1.0446E-18" iyy="0.0015444" iyz="-7.676E-06" izz="0.0011341"/>
    </inertial>
    <visual>
      <origin rpy="0 0 0" xyz="0 0 0"/>
      <geometry>
        <mesh filename="package://robot_urdf/meshes/support_right.STL"/>
      </geometry>
      <material name="">
        <color rgba="0.89804 0.91765 0.92941 1"/>
      </material>
    </visual>
    <collision>
      <origin rpy="0 0 0" xyz="0 0 0"/>
      <geometry>
        <mesh filename="package://robot_urdf/meshes/support_right.STL"/>
      </geometry>
    </collision>
  </link>
  <joint name="j_support_right" type="revolute">
    <origin rpy="0 0 0" xyz="0.2474 -0.15113 0.23622"/>
    <parent link="base_link"/>
    <child link="support_right"/>
    <axis xyz="0 0 1"/>
    <limit effort="10" lower="-1.0472" upper="1.0472" velocity="100"/>
  </joint>
  <link name="front_right_wheel">
    <inertial>
      <origin rpy="0 0 0" xyz="8.3267E-17 0.027268 0"/>
      <mass value="0.73792"/>
      <inertia ixx="0.0027981" ixy="1.5423E-17" ixz="-6.2886E-19" iyy="0.0051346" iyz="-8.1526E-19" izz="0.0027981"/>
    </inertial>
    <visual>
      <origin rpy="0 0 0" xyz="0 0 0"/>
      <geometry>
        <mesh filename="package://robot_urdf/meshes/front_right_wheel.STL"/>
      </geometry>
      <material name="">
        <color rgba="0.79216 0.81961 0.93333 1"/>
      </material>
    </visual>
    <collision>
      <origin rpy="0 0 0" xyz="0 0 0"/>
      <geometry>
        <mesh filename="package://robot_urdf/meshes/front_right_wheel.STL"/>
      </geometry>
    </collision>
  </link>
  <joint name="j_front_right_wheel" type="continuous">
    <origin rpy="0 0 0" xyz="0 -0.03048 -0.13462"/>
    <parent link="support_right"/>
    <child link="front_right_wheel"/>
    <axis xyz="0 -1 0"/>
    <limit effort="30" velocity="100"/>
  </joint>
  <link name="rear_left_wheel">
    <inertial>
      <origin rpy="0 0 0" xyz="-5.5511E-17 -0.027268 8.3267E-17"/>
      <mass value="0.73792"/>
      <inertia ixx="0.0027981" ixy="-1.8591E-19" ixz="-1.0264E-19" iyy="0.0051346" iyz="6.9316E-20" izz="0.0027981"/>
    </inertial>
    <visual>
      <origin rpy="0 0 0" xyz="0 0 0"/>
      <geometry>
        <mesh filename="package://robot_urdf/meshes/rear_left_wheel.STL"/>
      </geometry>
      <material name="">
        <color rgba="0.79216 0.81961 0.93333 1"/>
      </material>
    </visual>
    <collision>
      <origin rpy="0 0 0" xyz="0 0 0"/>
      <geometry>
        <mesh filename="package://robot_urdf/meshes/rear_left_wheel.STL"/>
      </geometry>
    </collision>
  </link>
  <joint name="j_rear_left_wheel" type="continuous">
    <origin rpy="0 0 0" xyz="-0.26061 0.18161 0.1016"/>
    <parent link="base_link"/>
    <child link="rear_left_wheel"/>
    <axis xyz="0 -1 0"/>
    <limit effort="30" velocity="100"/>
  </joint>
  <link name="rear_right_wheel">
    <inertial>
      <origin rpy="0 0 0" xyz="-1.1102E-16 0.033692 -4.1633E-17"/>
      <mass value="0.73792"/>
      <inertia ixx="0.0027981" ixy="-5.0215E-19" ixz="1.8606E-19" iyy="0.0051346" iyz="-4.1194E-20" izz="0.0027981"/>
    </inertial>
    <visual>
      <origin rpy="0 0 0" xyz="0 0 0"/>
      <geometry>
        <mesh filename="package://robot_urdf/meshes/rear_right_wheel.STL"/>
      </geometry>
      <material name="">
        <color rgba="0.79216 0.81961 0.93333 1"/>
      </material>
    </visual>
    <collision>
      <origin rpy="0 0 0" xyz="0 0 0"/>
      <geometry>
        <mesh filename="package://robot_urdf/meshes/rear_right_wheel.STL"/>
      </geometry>
    </collision>
  </link>
  <joint name="j_rear_right_wheel" type="continuous">
    <origin rpy="0 0 0" xyz="-0.26061 -0.18161 0.1016"/>
    <parent link="base_link"/>
    <child link="rear_right_wheel"/>
    <axis xyz="0 -1 0"/>
    <limit effort="30" velocity="100"/>
  </joint>
  <link name="base_laser">
    <inertial>
      <origin rpy="0 0 0" xyz="-0.00029774 0.0066667 0.00013047"/>
      <mass value="0.15717"/>
      <inertia ixx="6.7885E-05" ixy="-1.3987E-07" ixz="-8.1554E-07" iyy="0.00013173" iyz="-9.0932E-08" izz="7.1972E-05"/>
    </inertial>
    <visual>
      <origin rpy="0 0 0" xyz="0 0 0"/>
      <geometry>
        <mesh filename="package://robot_urdf/meshes/ydlidar.dae"/>
      </geometry>
      <material name="">
        <color rgba="0.64706 0.61961 0.58824 1"/>
      </material>
    </visual>
    <collision>
      <origin rpy="0 0 0" xyz="0 0 0"/>
      <geometry>
        <mesh filename="package://robot_urdf/meshes/ydlidar.dae"/>
      </geometry>
    </collision>
  </link>
  <link name="laser_frame">
    <inertial>
      <origin rpy="0 0 0" xyz="-0.00036659 0.00064155 -0.00027052"/>
      <mass value="0.25482"/>
      <inertia ixx="8.9194E-05" ixy="1.8116E-07" ixz="3.6435E-08" iyy="0.00018279" iyz="2.423E-07" izz="0.00011103"/>
    </inertial>
    <!--visual>
      <origin
        xyz="0 0 0"
        rpy="0 0 0" />
      <geometry>
        <mesh
          filename="package://ydlidar_ros/meshes/ydlidar.dae" />
      </geometry>
      <material
        name="">
        <color
          rgba="0.64706 0.61961 0.58824 1" />
      </material>
    </visual-->
    <!--collision>
      <origin
        xyz="0 0 0"
        rpy="0 0 0" />
      <geometry>
        <mesh
          filename="package://ydlidar_ros/meshes/ydlidar.dae" />
      </geometry>
    </collision-->
  </link>
  <joint name="laser_joint" type="fixed">
    <origin rpy="0 0 0" xyz="0 0 0.03172"/>
    <parent link="base_laser"/>
    <child link="laser_frame"/>
    <axis xyz="0 0 0"/>
  </joint>
  <!-- Add your gazebo sensors here -->
  <gazebo reference="base_laser">
    <!-- <gravity>true</gravity> -->
    <!-- Gazebo has fixed set of Sensors types. Check them out here <> -->
    <sensor name="laser" type="ray">
      <!-- Add in your sensor characteristics -->
      <pose> 0 0 0 0 0 0 </pose>
      <visualise>true</visualise>
      <update_rate>40</update_rate>
      <!-- <always_on>true</always_on> -->
      <ray>
        <scan>
          <horizontal>
            <samples>720</samples>
            <resolution>1</resolution>
            <min_angle>-1.570796</min_angle>
            <max_angle>1.570796</max_angle>
          </horizontal>
        </scan>
        <range>
          <min>0.10</min>
          <max>30.0</max>
          <resolution>0.01</resolution>
        </range>
        <noise>
          <type>gaussian</type>
          <mean>0.0</mean>
          <stddev>0.01</stddev>
        </noise>
      </ray>
      <plugin filename="libgazebo_ros_laser.so" name="gazebo_ros_head_hokuyo_controller">
        <!-- Use topic name as /my_robot/scan -->
        <topicName>/robot_urdf/laser_scan</topicName>
        <frameName>laser_frame</frameName>
      </plugin>
    </sensor>
  </gazebo>
  <!--  Gazebo plugin for control here is already added for you -->
  <gazebo>
    <plugin filename="libgazebo_ros_control.so" name="gazebo_ros_control">
      <robotNamespace>/robot_urdf/</robotNamespace>
      <robotSimType>gazebo_ros_control/DefaultRobotHWSim</robotSimType>
      <legacyModeNS>true</legacyModeNS>
    </plugin>
  </gazebo>
  <!-- Create a joint between your robot and sensor -->
  <joint name="sensor_joint" type="fixed">
    <origin rpy="0 0 0" xyz="0.525 0 0.2375"/>
    <parent link="dummy_link"/>
    <child link="base_laser"/>
  </joint>
  <material name="red">
    <color rgba="0.8 0.0 0.0 1.0"/>
  </material>
  <material name="black">
    <color rgba="0.0 0.0 0.0 1.0"/>
  </material>
  <material name="dark">
    <color rgba="0.3 0.3 0.3 1.0"/>
  </material>
  <gazebo reference="base_link">
    <material>Gazebo/SkyBlue</material>
  </gazebo>
  <gazebo reference="support_left">
    <material>Gazebo/SkyBlue</material>
  </gazebo>
  <gazebo reference="support_right">
    <material>Gazebo/SkyBlue</material>
  </gazebo>
  <gazebo reference="front_left_wheel">
    <material>Gazebo/Grey</material>
  </gazebo>
  <gazebo reference="front_right_wheel">
    <material>Gazebo/Grey</material>
  </gazebo>
  <gazebo reference="rear_left_wheel">
    <material>Gazebo/Grey</material>
  </gazebo>
  <gazebo reference="rear_right_wheel">
    <material>Gazebo/Grey</material>
  </gazebo>
  <link name="dummy_link">
	</link>
  <joint name="dummy_joint" type="fixed">
    <parent link="dummy_link"/>
    <child link="base_link"/>
  </joint>
  <transmission name="rear_drive_left">
    <type>transmission_interface/SimpleTransmission</type>
    <joint name="j_rear_left_wheel">
      <hardwareInterface>hardware_interface/VelocityJointInterface</hardwareInterface>
    </joint>
    <actuator name="rear_motor_left">
      <mechanicalReduction>1</mechanicalReduction>
    </actuator>
  </transmission>
  <transmission name="rear_drive_right">
    <type>transmission_interface/SimpleTransmission</type>
    <joint name="j_rear_right_wheel">
      <hardwareInterface>hardware_interface/VelocityJointInterface</hardwareInterface>
    </joint>
    <actuator name="rear_motor_right">
      <mechanicalReduction>1</mechanicalReduction>
    </actuator>
  </transmission>
  <transmission name="front_steering_left">
    <type>transmission_interface/SimpleTransmission</type>
    <joint name="j_support_left">
      <hardwareInterface>hardware_interface/EffortJointInterface</hardwareInterface>
    </joint>
    <actuator name="front_motor_left">
      <mechanicalReduction>1</mechanicalReduction>
    </actuator>
  </transmission>
  <transmission name="front_steering_right">
    <type>transmission_interface/SimpleTransmission</type>
    <joint name="j_support_right">
      <hardwareInterface>hardware_interface/EffortJointInterface</hardwareInterface>
    </joint>
    <actuator name="front_motor_right">
      <mechanicalReduction>1</mechanicalReduction>
    </actuator>
  </transmission>
</robot>
