<?xml version="1.0" ?>
<!-- =================================================================================== -->
<!-- |    This document was autogenerated by xacro from xacro/robot.xacro              | -->
<!-- |    EDITING THIS FILE BY HAND IS NOT RECOMMENDED                                 | -->
<!-- =================================================================================== -->
<!-- Name your robot here -->
<robot name="robot_urdf">
  <link name="base_link">
    <inertial>
      <origin rpy="0 0 0" xyz="-0.0077954581064524 -1.72316522734598E-06 0.241227552329224"/>
      <mass value="51.2225965563684"/>
      <inertia ixx="1.12008474839621" ixy="4.10428228302519E-05" ixz="-0.0357232741557662" iyy="4.04526054588228" iyz="5.12332120176019E-08" izz="5.1299324679939"/>
    </inertial>
    <visual>
      <origin rpy="0 0 0" xyz="0 0 0"/>
      <geometry>
        <mesh filename="package://robot_urdf/meshes/base_link.STL"/>
      </geometry>
      <material name="">
        <color rgba="0.898039215686275 0.917647058823529 0.929411764705882 1"/>
      </material>
    </visual>
    <collision>
      <origin rpy="0 0 0" xyz="0 0 0"/>
      <geometry>
        <mesh filename="package://robot_urdf/meshes/base_link.STL"/>
      </geometry>
    </collision>
  </link>
  <link name="support_left">
    <inertial>
      <origin rpy="0 0 0" xyz="1.11022302462516E-16 -0.000175745860538146 -0.0988551027510241"/>
      <mass value="0.511568168116717"/>
      <inertia ixx="0.00233331327511673" ixy="7.80611924549488E-20" ixz="1.48302718659022E-18" iyy="0.00169516860077224" iyz="-7.37347093187782E-06" izz="0.00113414228037386"/>
    </inertial>
    <visual>
      <origin rpy="0 0 0" xyz="0 0 0"/>
      <geometry>
        <mesh filename="package://robot_urdf/meshes/support_left.STL"/>
      </geometry>
      <material name="">
        <color rgba="0.898039215686275 0.917647058823529 0.929411764705882 1"/>
      </material>
    </visual>
    <collision>
      <origin rpy="0 0 0" xyz="0 0 0"/>
      <geometry>
        <mesh filename="package://robot_urdf/meshes/support_left.STL"/>
      </geometry>
    </collision>
  </link>
  <joint name="j_support_left" type="revolute">
    <origin rpy="0 0 0" xyz="0.3683 0.15113 0.24943"/>
    <parent link="base_link"/>
    <child link="support_left"/>
    <axis xyz="0 0 1"/>
    <limit effort="10" lower="-1.0472" upper="1.0472" velocity="100"/>
  </joint>
  <link name="front_left_wheel">
    <inertial>
      <origin rpy="0 0 0" xyz="0 -0.0272681474371538 -6.93889390390723E-17"/>
      <mass value="0.737916384214473"/>
      <inertia ixx="0.00279813808464154" ixy="6.47020074202444E-20" ixz="-1.55146384000578E-18" iyy="0.00513458608151511" iyz="3.20353968483808E-19" izz="0.00279813808464155"/>
    </inertial>
    <visual>
      <origin rpy="0 0 0" xyz="0 0 0"/>
      <geometry>
        <mesh filename="package://robot_urdf/meshes/front_left_wheel.STL"/>
      </geometry>
      <material name="">
        <color rgba="0.792156862745098 0.819607843137255 0.933333333333333 1"/>
      </material>
    </visual>
    <collision>
      <origin rpy="0 0 0" xyz="0 0 0"/>
      <geometry>
        <mesh filename="package://robot_urdf/meshes/front_left_wheel.STL"/>
      </geometry>
    </collision>
  </link>
  <joint name="j_front_left_wheel" type="continuous">
    <origin rpy="0 0 0" xyz="0 0.03048 -0.14732"/>
    <parent link="support_left"/>
    <child link="front_left_wheel"/>
    <axis xyz="0 -1 0"/>
    <limit effort="30" velocity="100"/>
  </joint>
  <link name="support_right">
    <inertial>
      <origin rpy="0 0 0" xyz="1.11022302462516E-16 -0.000175745860538229 -0.0988551027510242"/>
      <mass value="0.511568168116718"/>
      <inertia ixx="0.00233331327511673" ixy="4.81627040448131E-20" ixz="1.53131066763964E-18" iyy="0.00169516860077224" iyz="-7.37347093187839E-06" izz="0.00113414228037387"/>
    </inertial>
    <visual>
      <origin rpy="0 0 0" xyz="0 0 0"/>
      <geometry>
        <mesh filename="package://robot_urdf/meshes/support_right.STL"/>
      </geometry>
      <material name="">
        <color rgba="0.898039215686275 0.917647058823529 0.929411764705882 1"/>
      </material>
    </visual>
    <collision>
      <origin rpy="0 0 0" xyz="0 0 0"/>
      <geometry>
        <mesh filename="package://robot_urdf/meshes/support_right.STL"/>
      </geometry>
    </collision>
  </link>
  <joint name="j_support_right" type="revolute">
    <origin rpy="0 0 0" xyz="0.3683 -0.15113 0.24943"/>
    <parent link="base_link"/>
    <child link="support_right"/>
    <axis xyz="0 0 1"/>
    <limit effort="10" lower="-1.0472" upper="1.0472" velocity="100"/>
  </joint>
  <link name="front_right_wheel">
    <inertial>
      <origin rpy="0 0 0" xyz="-1.11022302462516E-16 0.0272681474371539 4.16333634234434E-17"/>
      <mass value="0.737916384214473"/>
      <inertia ixx="0.00279813808464155" ixy="6.71133983372056E-19" ixz="2.82564897248114E-18" iyy="0.00513458608151511" iyz="-1.02883637816587E-18" izz="0.00279813808464154"/>
    </inertial>
    <visual>
      <origin rpy="0 0 0" xyz="0 0 0"/>
      <geometry>
        <mesh filename="package://robot_urdf/meshes/front_right_wheel.STL"/>
      </geometry>
      <material name="">
        <color rgba="0.792156862745098 0.819607843137255 0.933333333333333 1"/>
      </material>
    </visual>
    <collision>
      <origin rpy="0 0 0" xyz="0 0 0"/>
      <geometry>
        <mesh filename="package://robot_urdf/meshes/front_right_wheel.STL"/>
      </geometry>
    </collision>
  </link>
  <joint name="j_front_right_wheel" type="continuous">
    <origin rpy="0 0 0" xyz="0 -0.03048 -0.14732"/>
    <parent link="support_right"/>
    <child link="front_right_wheel"/>
    <axis xyz="0 -1 0"/>
    <limit effort="30" velocity="100"/>
  </joint>
  <link name="rear_left_wheel">
    <inertial>
      <origin rpy="0 0 0" xyz="-5.55111512312578E-17 -0.0272681474371538 2.77555756156289E-17"/>
      <mass value="0.737916384214473"/>
      <inertia ixx="0.00279813808464154" ixy="1.11590459934088E-19" ixz="-2.45201083392975E-18" iyy="0.0051345860815151" iyz="1.67351097464878E-19" izz="0.00279813808464155"/>
    </inertial>
    <visual>
      <origin rpy="0 0 0" xyz="0 0 0"/>
      <geometry>
        <mesh filename="package://robot_urdf/meshes/rear_left_wheel.STL"/>
      </geometry>
      <material name="">
        <color rgba="0.792156862745098 0.819607843137255 0.933333333333333 1"/>
      </material>
    </visual>
    <collision>
      <origin rpy="0 0 0" xyz="0 0 0"/>
      <geometry>
        <mesh filename="package://robot_urdf/meshes/rear_left_wheel.STL"/>
      </geometry>
    </collision>
  </link>
  <joint name="j_rear_left_wheel" type="continuous">
    <origin rpy="0 0 0" xyz="-0.381 0.18161 0.10211"/>
    <parent link="base_link"/>
    <child link="rear_left_wheel"/>
    <axis xyz="0 -1 0"/>
    <limit effort="30" velocity="100"/>
  </joint>
  <link name="rear_right_wheel">
    <inertial>
      <origin rpy="0 0 0" xyz="-1.11022302462516E-16 0.0336918525628461 -2.77555756156289E-17"/>
      <mass value="0.737916384214473"/>
      <inertia ixx="0.00279813808464154" ixy="-4.92403285766757E-19" ixz="-1.01956744195369E-18" iyy="0.0051345860815151" iyz="3.79673346254853E-20" izz="0.00279813808464154"/>
    </inertial>
    <visual>
      <origin rpy="0 0 0" xyz="0 0 0"/>
      <geometry>
        <mesh filename="package://robot_urdf/meshes/rear_right_wheel.STL"/>
      </geometry>
      <material name="">
        <color rgba="0.792156862745098 0.819607843137255 0.933333333333333 1"/>
      </material>
    </visual>
    <collision>
      <origin rpy="0 0 0" xyz="0 0 0"/>
      <geometry>
        <mesh filename="package://robot_urdf/meshes/rear_right_wheel.STL"/>
      </geometry>
    </collision>
  </link>
  <joint name="j_rear_right_wheel" type="continuous">
    <origin rpy="0 0 0" xyz="-0.381 -0.18161 0.10211"/>
    <parent link="base_link"/>
    <child link="rear_right_wheel"/>
    <axis xyz="0 -1 0"/>
    <limit effort="30" velocity="100"/>
  </joint>
  <link name="base_laser">
    <inertial>
      <origin rpy="0 0 0" xyz="-0.00029774 0.0066667 0.00013047"/>
      <mass value="0.15717"/>
      <inertia ixx="6.7885E-05" ixy="-1.3987E-07" ixz="-8.1554E-07" iyy="0.00013173" iyz="-9.0932E-08" izz="7.1972E-05"/>
    </inertial>
    <visual>
      <origin rpy="0 0 0" xyz="0 0 0"/>
      <geometry>
        <mesh filename="package://robot_urdf/meshes/ydlidar.dae"/>
      </geometry>
      <material name="">
        <color rgba="0.64706 0.61961 0.58824 1"/>
      </material>
    </visual>
    <collision>
      <origin rpy="0 0 0" xyz="0 0 0"/>
      <geometry>
        <mesh filename="package://robot_urdf/meshes/ydlidar.dae"/>
      </geometry>
    </collision>
  </link>
  <link name="laser_frame">
    <inertial>
      <origin rpy="0 0 0" xyz="-0.00036659 0.00064155 -0.00027052"/>
      <mass value="0.25482"/>
      <inertia ixx="8.9194E-05" ixy="1.8116E-07" ixz="3.6435E-08" iyy="0.00018279" iyz="2.423E-07" izz="0.00011103"/>
    </inertial>
    <!--visual>
      <origin
        xyz="0 0 0"
        rpy="0 0 0" />
      <geometry>
        <mesh
          filename="package://ydlidar_ros/meshes/ydlidar.dae" />
      </geometry>
      <material
        name="">
        <color
          rgba="0.64706 0.61961 0.58824 1" />
      </material>
    </visual-->
    <!--collision>
      <origin
        xyz="0 0 0"
        rpy="0 0 0" />
      <geometry>
        <mesh
          filename="package://ydlidar_ros/meshes/ydlidar.dae" />
      </geometry>
    </collision-->
  </link>
  <joint name="laser_joint" type="fixed">
    <origin rpy="0 0 0" xyz="0 0 0.03172"/>
    <parent link="base_laser"/>
    <child link="laser_frame"/>
    <axis xyz="0 0 0"/>
  </joint>
  <!-- Add your gazebo sensors here -->
  <gazebo reference="base_laser">
    <!-- <gravity>true</gravity> -->
    <!-- Gazebo has fixed set of Sensors types. Check them out here <> -->
    <sensor name="laser" type="ray">
      <!-- Add in your sensor characteristics -->
      <pose> 0 0 0 0 0 0 </pose>
      <visualise>true</visualise>
      <update_rate>40</update_rate>
      <!-- <always_on>true</always_on> -->
      <ray>
        <scan>
          <horizontal>
            <samples>720</samples>
            <resolution>1</resolution>
            <min_angle>-1.570796</min_angle>
            <max_angle>1.570796</max_angle>
          </horizontal>
        </scan>
        <range>
          <min>0.10</min>
          <max>30.0</max>
          <resolution>0.01</resolution>
        </range>
        <noise>
          <type>gaussian</type>
          <mean>0.0</mean>
          <stddev>0.01</stddev>
        </noise>
      </ray>
      <plugin filename="libgazebo_ros_laser.so" name="gazebo_ros_head_hokuyo_controller">
        <!-- Use topic name as /my_robot/scan -->
        <topicName>/robot_urdf/laser_scan</topicName>
        <frameName>laser_frame</frameName>
      </plugin>
    </sensor>
  </gazebo>
  <!--  Gazebo plugin for control here is already added for you -->
  <gazebo>
    <plugin filename="libgazebo_ros_control.so" name="gazebo_ros_control">
      <robotNamespace>/robot_urdf/</robotNamespace>
      <robotSimType>gazebo_ros_control/DefaultRobotHWSim</robotSimType>
      <legacyModeNS>true</legacyModeNS>
    </plugin>
  </gazebo>
  <!-- Create a joint between your robot and sensor -->
  <joint name="sensor_joint" type="fixed">
    <origin rpy="0 0 0" xyz="0.45 0 0.265"/>
    <parent link="dummy_link"/>
    <child link="base_laser"/>
  </joint>
  <material name="red">
    <color rgba="0.8 0.0 0.0 1.0"/>
  </material>
  <material name="black">
    <color rgba="0.0 0.0 0.0 1.0"/>
  </material>
  <material name="dark">
    <color rgba="0.3 0.3 0.3 1.0"/>
  </material>
  <gazebo reference="base_link">
    <material>Gazebo/Red</material>
  </gazebo>
  <gazebo reference="support_left">
    <material>Gazebo/Red</material>
  </gazebo>
  <gazebo reference="support_right">
    <material>Gazebo/Red</material>
  </gazebo>
  <gazebo reference="front_left_wheel">
    <material>Gazebo/FlatBlack</material>
  </gazebo>
  <gazebo reference="front_right_wheel">
    <material>Gazebo/FlatBlack</material>
  </gazebo>
  <gazebo reference="rear_left_wheel">
    <material>Gazebo/FlatBlack</material>
  </gazebo>
  <gazebo reference="rear_right_wheel">
    <material>Gazebo/FlatBlack</material>
  </gazebo>
  <link name="dummy_link">
	</link>
  <joint name="dummy_joint" type="fixed">
    <parent link="dummy_link"/>
    <child link="base_link"/>
  </joint>
  <transmission name="rear_drive_left">
    <type>transmission_interface/SimpleTransmission</type>
    <joint name="j_rear_left_wheel">
      <hardwareInterface>hardware_interface/VelocityJointInterface</hardwareInterface>
    </joint>
    <actuator name="rear_motor_left">
      <mechanicalReduction>1</mechanicalReduction>
    </actuator>
  </transmission>
  <transmission name="rear_drive_right">
    <type>transmission_interface/SimpleTransmission</type>
    <joint name="j_rear_right_wheel">
      <hardwareInterface>hardware_interface/VelocityJointInterface</hardwareInterface>
    </joint>
    <actuator name="rear_motor_right">
      <mechanicalReduction>1</mechanicalReduction>
    </actuator>
  </transmission>
  <transmission name="front_steering_left">
    <type>transmission_interface/SimpleTransmission</type>
    <joint name="j_support_left">
      <hardwareInterface>hardware_interface/EffortJointInterface</hardwareInterface>
    </joint>
    <actuator name="front_motor_left">
      <mechanicalReduction>1</mechanicalReduction>
    </actuator>
  </transmission>
  <transmission name="front_steering_right">
    <type>transmission_interface/SimpleTransmission</type>
    <joint name="j_support_right">
      <hardwareInterface>hardware_interface/EffortJointInterface</hardwareInterface>
    </joint>
    <actuator name="front_motor_right">
      <mechanicalReduction>1</mechanicalReduction>
    </actuator>
  </transmission>
</robot>
