<?xml version="1.0" encoding="utf-8"?>
<!-- This URDF was automatically created by SolidWorks to URDF Exporter! Originally created by Stephen Brawner (brawner@gmail.com) 
     Commit Version: 1.6.0-4-g7f85cfe  Build Version: 1.6.7995.38578
     For more information, please see http://wiki.ros.org/sw_urdf_exporter -->
<robot
  name="robot_urdf">
  <link
    name="base_link">
    <inertial>
      <origin
        xyz="0.033945 0.00011949 0.23682"
        rpy="0 0 0" />
      <mass
        value="21.354" />
      <inertia
        ixx="0.49496"
        ixy="-0.00077943"
        ixz="0.11652"
        iyy="1.7969"
        iyz="3.3785E-05"
        izz="2.1422" />
    </inertial>
    <visual>
      <origin
        xyz="0 0 0"
        rpy="0 0 0" />
      <geometry>
        <mesh
          filename="package://robot_urdf/meshes/base_link.STL" />
      </geometry>
      <material
        name="">
        <color
          rgba="0.79216 0.81961 0.93333 1" />
      </material>
    </visual>
    <collision>
      <origin
        xyz="0 0 0"
        rpy="0 0 0" />
      <geometry>
        <mesh
          filename="package://robot_urdf/meshes/base_link.STL" />
      </geometry>
    </collision>
  </link>
  <link
    name="support_left">
    <inertial>
      <origin
        xyz="-1.6376E-15 -0.00017575 -0.095491"
        rpy="0 0 0" />
      <mass
        value="0.51157" />
      <inertia
        ixx="0.0021825"
        ixy="5.816E-18"
        ixz="1.9269E-18"
        iyy="0.0015444"
        iyz="-7.676E-06"
        izz="0.0011341" />
    </inertial>
    <visual>
      <origin
        xyz="0 0 0"
        rpy="0 0 0" />
      <geometry>
        <mesh
          filename="package://robot_urdf/meshes/support_left.STL" />
      </geometry>
      <material
        name="">
        <color
          rgba="0.89804 0.91765 0.92941 1" />
      </material>
    </visual>
    <collision>
      <origin
        xyz="0 0 0"
        rpy="0 0 0" />
      <geometry>
        <mesh
          filename="package://robot_urdf/meshes/support_left.STL" />
      </geometry>
    </collision>
  </link>
  <joint
    name="j_support_left"
    type="revolute">
    <origin
      xyz="0.2474 0.15113 0.23622"
      rpy="0 0 0" />
    <parent
      link="base_link" />
    <child
      link="support_left" />
    <axis
      xyz="0 0 1" />
    <limit
      lower="-1.0472"
      upper="1.0472"
      effort="10"
      velocity="100" />
  </joint>
  <link
    name="front_left_wheel">
    <inertial>
      <origin
        xyz="1.3878E-16 -0.027268 -2.7756E-17"
        rpy="0 0 0" />
      <mass
        value="0.73792" />
      <inertia
        ixx="0.0027981"
        ixy="-1.7241E-17"
        ixz="-2.1031E-18"
        iyy="0.0051346"
        iyz="1.7405E-18"
        izz="0.0027981" />
    </inertial>
    <visual>
      <origin
        xyz="0 0 0"
        rpy="0 0 0" />
      <geometry>
        <mesh
          filename="package://robot_urdf/meshes/front_left_wheel.STL" />
      </geometry>
      <material
        name="">
        <color
          rgba="0.79216 0.81961 0.93333 1" />
      </material>
    </visual>
    <collision>
      <origin
        xyz="0 0 0"
        rpy="0 0 0" />
      <geometry>
        <mesh
          filename="package://robot_urdf/meshes/front_left_wheel.STL" />
      </geometry>
    </collision>
  </link>
  <joint
    name="j_front_left_wheel"
    type="continuous">
    <origin
      xyz="0 0.03048 -0.13462"
      rpy="0 0 0" />
    <parent
      link="support_left" />
    <child
      link="front_left_wheel" />
    <axis
      xyz="0 -1 0" />
    <limit
      effort="30"
      velocity="100" />
  </joint>
  <link
    name="support_right">
    <inertial>
      <origin
        xyz="1.1102E-16 -0.00017575 -0.095491"
        rpy="0 0 0" />
      <mass
        value="0.51157" />
      <inertia
        ixx="0.0021825"
        ixy="-3.401E-18"
        ixz="1.0446E-18"
        iyy="0.0015444"
        iyz="-7.676E-06"
        izz="0.0011341" />
    </inertial>
    <visual>
      <origin
        xyz="0 0 0"
        rpy="0 0 0" />
      <geometry>
        <mesh
          filename="package://robot_urdf/meshes/support_right.STL" />
      </geometry>
      <material
        name="">
        <color
          rgba="0.89804 0.91765 0.92941 1" />
      </material>
    </visual>
    <collision>
      <origin
        xyz="0 0 0"
        rpy="0 0 0" />
      <geometry>
        <mesh
          filename="package://robot_urdf/meshes/support_right.STL" />
      </geometry>
    </collision>
  </link>
  <joint
    name="j_support_right"
    type="revolute">
    <origin
      xyz="0.2474 -0.15113 0.23622"
      rpy="0 0 0" />
    <parent
      link="base_link" />
    <child
      link="support_right" />
    <axis
      xyz="0 0 1" />
    <limit
      lower="-1.0472"
      upper="1.0472"
      effort="10"
      velocity="100" />
  </joint>
  <link
    name="front_right_wheel">
    <inertial>
      <origin
        xyz="8.3267E-17 0.027268 0"
        rpy="0 0 0" />
      <mass
        value="0.73792" />
      <inertia
        ixx="0.0027981"
        ixy="1.5423E-17"
        ixz="-6.2886E-19"
        iyy="0.0051346"
        iyz="-8.1526E-19"
        izz="0.0027981" />
    </inertial>
    <visual>
      <origin
        xyz="0 0 0"
        rpy="0 0 0" />
      <geometry>
        <mesh
          filename="package://robot_urdf/meshes/front_right_wheel.STL" />
      </geometry>
      <material
        name="">
        <color
          rgba="0.79216 0.81961 0.93333 1" />
      </material>
    </visual>
    <collision>
      <origin
        xyz="0 0 0"
        rpy="0 0 0" />
      <geometry>
        <mesh
          filename="package://robot_urdf/meshes/front_right_wheel.STL" />
      </geometry>
    </collision>
  </link>
  <joint
    name="j_front_right_wheel"
    type="continuous">
    <origin
      xyz="0 -0.03048 -0.13462"
      rpy="0 0 0" />
    <parent
      link="support_right" />
    <child
      link="front_right_wheel" />
    <axis
      xyz="0 -1 0" />
    <limit
      effort="30"
      velocity="100" />
  </joint>
  <link
    name="rear_left_wheel">
    <inertial>
      <origin
        xyz="-5.5511E-17 -0.027268 8.3267E-17"
        rpy="0 0 0" />
      <mass
        value="0.73792" />
      <inertia
        ixx="0.0027981"
        ixy="-1.8591E-19"
        ixz="-1.0264E-19"
        iyy="0.0051346"
        iyz="6.9316E-20"
        izz="0.0027981" />
    </inertial>
    <visual>
      <origin
        xyz="0 0 0"
        rpy="0 0 0" />
      <geometry>
        <mesh
          filename="package://robot_urdf/meshes/rear_left_wheel.STL" />
      </geometry>
      <material
        name="">
        <color
          rgba="0.79216 0.81961 0.93333 1" />
      </material>
    </visual>
    <collision>
      <origin
        xyz="0 0 0"
        rpy="0 0 0" />
      <geometry>
        <mesh
          filename="package://robot_urdf/meshes/rear_left_wheel.STL" />
      </geometry>
    </collision>
  </link>
  <joint
    name="j_rear_left_wheel"
    type="continuous">
    <origin
      xyz="-0.26061 0.18161 0.1016"
      rpy="0 0 0" />
    <parent
      link="base_link" />
    <child
      link="rear_left_wheel" />
    <axis
      xyz="0 -1 0" />
    <limit
      effort="30"
      velocity="100" />
  </joint>
  <link
    name="rear_right_wheel">
    <inertial>
      <origin
        xyz="-1.1102E-16 0.033692 -4.1633E-17"
        rpy="0 0 0" />
      <mass
        value="0.73792" />
      <inertia
        ixx="0.0027981"
        ixy="-5.0215E-19"
        ixz="1.8606E-19"
        iyy="0.0051346"
        iyz="-4.1194E-20"
        izz="0.0027981" />
    </inertial>
    <visual>
      <origin
        xyz="0 0 0"
        rpy="0 0 0" />
      <geometry>
        <mesh
          filename="package://robot_urdf/meshes/rear_right_wheel.STL" />
      </geometry>
      <material
        name="">
        <color
          rgba="0.79216 0.81961 0.93333 1" />
      </material>
    </visual>
    <collision>
      <origin
        xyz="0 0 0"
        rpy="0 0 0" />
      <geometry>
        <mesh
          filename="package://robot_urdf/meshes/rear_right_wheel.STL" />
      </geometry>
    </collision>
  </link>
  <joint
    name="j_rear_right_wheel"
    type="continuous">
    <origin
      xyz="-0.26061 -0.18161 0.1016"
      rpy="0 0 0" />
    <parent
      link="base_link" />
    <child
      link="rear_right_wheel" />
    <axis
      xyz="0 -1 0" />
    <limit
      effort="30"
      velocity="100" />
  </joint>
</robot>