<?xml version="1.0" encoding="utf-8"?>
<!-- This URDF was automatically created by SolidWorks to URDF Exporter! Originally created by Stephen Brawner (brawner@gmail.com) 
     Commit Version: 1.6.0-4-g7f85cfe  Build Version: 1.6.7995.38578
     For more information, please see http://wiki.ros.org/sw_urdf_exporter -->
<robot
  name="robot_urdf">
  <link
    name="base_link">
    <inertial>
      <origin
        xyz="-0.00698092133439408 -1.72591907613244E-06 0.254999556107946"
        rpy="0 0 0" />
      <mass
        value="51.1408666026729" />
      <inertia
        ixx="1.11587336793629"
        ixy="4.0970927744624E-05"
        ixz="-0.0288078810235416"
        iyy="4.02386606788245"
        iyz="2.38707294259556E-08"
        izz="5.10871768208811" />
    </inertial>
    <visual>
      <origin
        xyz="0 0 0"
        rpy="0 0 0" />
      <geometry>
        <mesh
          filename="package://robot_urdf/meshes/base_link.STL" />
      </geometry>
      <material
        name="">
        <color
          rgba="0.898039215686275 0.917647058823529 0.929411764705882 1" />
      </material>
    </visual>
    <collision>
      <origin
        xyz="0 0 0"
        rpy="0 0 0" />
      <geometry>
        <mesh
          filename="package://robot_urdf/meshes/base_link.STL" />
      </geometry>
    </collision>
  </link>
  <link
    name="support_left">
    <inertial>
      <origin
        xyz="2.27595720048157E-15 -0.000293612421093603 -0.0767006385266942"
        rpy="0 0 0" />
      <mass
        value="0.141762199312228" />
      <inertia
        ixx="0.000668283033387974"
        ixy="-4.83047329099128E-19"
        ixz="3.03478451631884E-19"
        iyy="0.000556501183749652"
        iyz="-4.22234085664355E-06"
        izz="0.000441916567523273" />
    </inertial>
    <visual>
      <origin
        xyz="0 0 0"
        rpy="0 0 0" />
      <geometry>
        <mesh
          filename="package://robot_urdf/meshes/support_left.STL" />
      </geometry>
      <material
        name="">
        <color
          rgba="0.792156862745098 0.819607843137255 0.933333333333333 1" />
      </material>
    </visual>
    <collision>
      <origin
        xyz="0 0 0"
        rpy="0 0 0" />
      <geometry>
        <mesh
          filename="package://robot_urdf/meshes/support_left.STL" />
      </geometry>
    </collision>
  </link>
  <joint
    name="j_support_left"
    type="revolute">
    <origin
      xyz="0.368299999999998 0.152399999999998 0.26289"
      rpy="0 0 0" />
    <parent
      link="base_link" />
    <child
      link="support_left" />
    <axis
      xyz="0 0 1" />
    <limit
      lower="-1.0472"
      upper="1.0472"
      effort="10"
      velocity="100" />
  </joint>
  <link
    name="front_left_wheel">
    <inertial>
      <origin
        xyz="-8.93729534823251E-15 5.08204589522165E-14 -0.030000000001089"
        rpy="0 0 0" />
      <mass
        value="5.71507847538447" />
      <inertia
        ixx="0.0206714901181664"
        ixy="-3.07999650944405E-15"
        ixz="-1.52176080705458E-15"
        iyy="0.0206714901189933"
        iyz="-7.03694690751749E-15"
        izz="0.037921181347593" />
    </inertial>
    <visual>
      <origin
        xyz="0 0 0"
        rpy="0 0 0" />
      <geometry>
        <mesh
          filename="package://robot_urdf/meshes/front_left_wheel.STL" />
      </geometry>
      <material
        name="">
        <color
          rgba="0.898039215686275 0.917647058823529 0.929411764705882 1" />
      </material>
    </visual>
    <collision>
      <origin
        xyz="0 0 0"
        rpy="0 0 0" />
      <geometry>
        <mesh
          filename="package://robot_urdf/meshes/front_left_wheel.STL" />
      </geometry>
    </collision>
  </link>
  <joint
    name="j_front_left_wheel"
    type="continuous">
    <origin
      xyz="0 -0.0299999999999973 -0.14732"
      rpy="1.5707963267949 0 0" />
    <parent
      link="support_left" />
    <child
      link="front_left_wheel" />
    <axis
      xyz="0 0 -1" />
    <limit
      effort="30"
      velocity="100" />
  </joint>
  <link
    name="support_right">
    <inertial>
      <origin
        xyz="-2.22044604925031E-16 0.000293612421096434 -0.0767006385266943"
        rpy="0 0 0" />
      <mass
        value="0.141762199312228" />
      <inertia
        ixx="0.000668283033387972"
        ixy="-3.64993126381272E-19"
        ixz="1.32058390166985E-19"
        iyy="0.00055650118374965"
        iyz="4.22234085664436E-06"
        izz="0.000441916567523273" />
    </inertial>
    <visual>
      <origin
        xyz="0 0 0"
        rpy="0 0 0" />
      <geometry>
        <mesh
          filename="package://robot_urdf/meshes/support_right.STL" />
      </geometry>
      <material
        name="">
        <color
          rgba="0.792156862745098 0.819607843137255 0.933333333333333 1" />
      </material>
    </visual>
    <collision>
      <origin
        xyz="0 0 0"
        rpy="0 0 0" />
      <geometry>
        <mesh
          filename="package://robot_urdf/meshes/support_right.STL" />
      </geometry>
    </collision>
  </link>
  <joint
    name="j_support_right"
    type="revolute">
    <origin
      xyz="0.3683 -0.1524 0.26289"
      rpy="0 0 0" />
    <parent
      link="base_link" />
    <child
      link="support_right" />
    <axis
      xyz="0 0 1" />
    <limit
      lower="-1.0472"
      upper="1.0472"
      effort="30"
      velocity="100" />
  </joint>
  <link
    name="front_right_wheel">
    <inertial>
      <origin
        xyz="1.98729921407903E-14 -5.20278264914964E-14 -0.0299999999989118"
        rpy="0 0 0" />
      <mass
        value="5.71507847538445" />
      <inertia
        ixx="0.0206714901183594"
        ixy="-3.49911584476704E-13"
        ixz="4.05678793278916E-15"
        iyy="0.0206714901187996"
        iyz="-5.00102978907231E-15"
        izz="0.0379211813475925" />
    </inertial>
    <visual>
      <origin
        xyz="0 0 0"
        rpy="0 0 0" />
      <geometry>
        <mesh
          filename="package://robot_urdf/meshes/front_right_wheel.STL" />
      </geometry>
      <material
        name="">
        <color
          rgba="0.898039215686275 0.917647058823529 0.929411764705882 1" />
      </material>
    </visual>
    <collision>
      <origin
        xyz="0 0 0"
        rpy="0 0 0" />
      <geometry>
        <mesh
          filename="package://robot_urdf/meshes/front_right_wheel.STL" />
      </geometry>
    </collision>
  </link>
  <joint
    name="j_front_right_wheel"
    type="continuous">
    <origin
      xyz="0 -0.0299999999999997 -0.14732"
      rpy="1.5707963267949 0 0" />
    <parent
      link="support_right" />
    <child
      link="front_right_wheel" />
    <axis
      xyz="0 0 -1" />
    <limit
      effort="30"
      velocity="100" />
  </joint>
  <link
    name="rear_left_wheel">
    <inertial>
      <origin
        xyz="3.51385587293862E-14 -4.57273108267486E-14 0.0300000000010904"
        rpy="0 0 0" />
      <mass
        value="5.71507847538444" />
      <inertia
        ixx="0.0206714901186204"
        ixy="-4.11316190814811E-13"
        ixz="6.3571271499716E-15"
        iyy="0.0206714901185395"
        iyz="-4.17569604207137E-15"
        izz="0.0379211813475923" />
    </inertial>
    <visual>
      <origin
        xyz="0 0 0"
        rpy="0 0 0" />
      <geometry>
        <mesh
          filename="package://robot_urdf/meshes/rear_left_wheel.STL" />
      </geometry>
      <material
        name="">
        <color
          rgba="0.898039215686275 0.917647058823529 0.929411764705882 1" />
      </material>
    </visual>
    <collision>
      <origin
        xyz="0 0 0"
        rpy="0 0 0" />
      <geometry>
        <mesh
          filename="package://robot_urdf/meshes/rear_left_wheel.STL" />
      </geometry>
    </collision>
  </link>
  <joint
    name="j_rear_left_wheel"
    type="continuous">
    <origin
      xyz="-0.3683 0.18113 0.11557"
      rpy="1.5707963267949 0 0" />
    <parent
      link="base_link" />
    <child
      link="rear_left_wheel" />
    <axis
      xyz="0 0 1" />
  </joint>
  <link
    name="rear_right_wheel">
    <inertial>
      <origin
        xyz="-5.60662627435704E-14 5.4678483962789E-15 -0.0300000000010884"
        rpy="0 0 0" />
      <mass
        value="5.71507847538442" />
      <inertia
        ixx="0.020671490118945"
        ixy="-1.92999249043331E-13"
        ixz="5.92317823464208E-15"
        iyy="0.0206714901182138"
        iyz="-2.67638866711897E-15"
        izz="0.0379211813475923" />
    </inertial>
    <visual>
      <origin
        xyz="0 0 0"
        rpy="0 0 0" />
      <geometry>
        <mesh
          filename="package://robot_urdf/meshes/rear_right_wheel.STL" />
      </geometry>
      <material
        name="">
        <color
          rgba="0.898039215686275 0.917647058823529 0.929411764705882 1" />
      </material>
    </visual>
    <collision>
      <origin
        xyz="0 0 0"
        rpy="0 0 0" />
      <geometry>
        <mesh
          filename="package://robot_urdf/meshes/rear_right_wheel.STL" />
      </geometry>
    </collision>
  </link>
  <joint
    name="j_rear_right_wheel"
    type="continuous">
    <origin
      xyz="-0.3683 -0.18113 0.11557"
      rpy="1.5707963267949 0 0" />
    <parent
      link="base_link" />
    <child
      link="rear_right_wheel" />
    <axis
      xyz="0 0 1" />
    <limit
      effort="30"
      velocity="100" />
  </joint>
  <transmission name="rear_drive_left">
    <type>transmission_interface/SimpleTransmission</type>
    <joint name="j_rear_left_wheel">
      <hardwareInterface>hardware_interface/VelocityJointInterface</hardwareInterface>
    </joint>
    <actuator name="rear_motor_left">
      <mechanicalReduction>1</mechanicalReduction>
    </actuator>
  </transmission>
  <transmission name="rear_drive_right">
    <type>transmission_interface/SimpleTransmission</type>
    <joint name="j_rear_right_wheel">
      <hardwareInterface>hardware_interface/VelocityJointInterface</hardwareInterface>
    </joint>
    <actuator name="rear_motor_right">
      <mechanicalReduction>1</mechanicalReduction>
    </actuator>
  </transmission>
  <transmission name="front_steering_left">
    <type>transmission_interface/SimpleTransmission</type>
    <joint name="j_support_left">
      <hardwareInterface>hardware_interface/EffortJointInterface</hardwareInterface>
    </joint>
    <actuator name="front_motor_left">
      <mechanicalReduction>1</mechanicalReduction>
    </actuator>
  </transmission>
  <transmission name="front_steering_right">
    <type>transmission_interface/SimpleTransmission</type>
    <joint name="j_support_right">
      <hardwareInterface>hardware_interface/EffortJointInterface</hardwareInterface>
    </joint>
    <actuator name="front_motor_right">
      <mechanicalReduction>1</mechanicalReduction>
    </actuator>
  </transmission>
</robot>