<?xml version="1.0" encoding="utf-8"?>
<!-- This URDF was automatically created by SolidWorks to URDF Exporter! Originally created by Stephen Brawner (brawner@gmail.com) 
     Commit Version: 1.6.0-4-g7f85cfe  Build Version: 1.6.7995.38578
     For more information, please see http://wiki.ros.org/sw_urdf_exporter -->
<robot
  name="robot_urdf">
  <link
    name="base_link">
    <inertial>
      <origin
        xyz="-0.0077954581064524 -1.72316522734598E-06 0.241227552329224"
        rpy="0 0 0" />
      <mass
        value="51.2225965563684" />
      <inertia
        ixx="1.12008474839621"
        ixy="4.10428228302519E-05"
        ixz="-0.0357232741557662"
        iyy="4.04526054588228"
        iyz="5.12332120176019E-08"
        izz="5.1299324679939" />
    </inertial>
    <visual>
      <origin
        xyz="0 0 0"
        rpy="0 0 0" />
      <geometry>
        <mesh
          filename="package://robot_urdf/meshes/base_link.STL" />
      </geometry>
      <material
        name="">
        <color
          rgba="0.898039215686275 0.917647058823529 0.929411764705882 1" />
      </material>
    </visual>
    <collision>
      <origin
        xyz="0 0 0"
        rpy="0 0 0" />
      <geometry>
        <mesh
          filename="package://robot_urdf/meshes/base_link.STL" />
      </geometry>
    </collision>
  </link>
  <link
    name="support_left">
    <inertial>
      <origin
        xyz="1.11022302462516E-16 -0.000175745860538146 -0.0988551027510241"
        rpy="0 0 0" />
      <mass
        value="0.511568168116717" />
      <inertia
        ixx="0.00233331327511673"
        ixy="7.80611924549488E-20"
        ixz="1.48302718659022E-18"
        iyy="0.00169516860077224"
        iyz="-7.37347093187782E-06"
        izz="0.00113414228037386" />
    </inertial>
    <visual>
      <origin
        xyz="0 0 0"
        rpy="0 0 0" />
      <geometry>
        <mesh
          filename="package://robot_urdf/meshes/support_left.STL" />
      </geometry>
      <material
        name="">
        <color
          rgba="0.898039215686275 0.917647058823529 0.929411764705882 1" />
      </material>
    </visual>
    <collision>
      <origin
        xyz="0 0 0"
        rpy="0 0 0" />
      <geometry>
        <mesh
          filename="package://robot_urdf/meshes/support_left.STL" />
      </geometry>
    </collision>
  </link>
  <joint
    name="j_support_left"
    type="revolute">
    <origin
      xyz="0.3683 0.15113 0.24943"
      rpy="0 0 0" />
    <parent
      link="base_link" />
    <child
      link="support_left" />
    <axis
      xyz="0 0 1" />
    <limit
      lower="-1.0472"
      upper="1.0472"
      effort="10"
      velocity="100" />
  </joint>
  <link
    name="front_left_wheel">
    <inertial>
      <origin
        xyz="0 -0.0272681474371538 -6.93889390390723E-17"
        rpy="0 0 0" />
      <mass
        value="0.737916384214473" />
      <inertia
        ixx="0.00279813808464154"
        ixy="6.47020074202444E-20"
        ixz="-1.55146384000578E-18"
        iyy="0.00513458608151511"
        iyz="3.20353968483808E-19"
        izz="0.00279813808464155" />
    </inertial>
    <visual>
      <origin
        xyz="0 0 0"
        rpy="0 0 0" />
      <geometry>
        <mesh
          filename="package://robot_urdf/meshes/front_left_wheel.STL" />
      </geometry>
      <material
        name="">
        <color
          rgba="0.792156862745098 0.819607843137255 0.933333333333333 1" />
      </material>
    </visual>
    <collision>
      <origin
        xyz="0 0 0"
        rpy="0 0 0" />
      <geometry>
        <mesh
          filename="package://robot_urdf/meshes/front_left_wheel.STL" />
      </geometry>
    </collision>
  </link>
  <joint
    name="j_front_left_wheel"
    type="continuous">
    <origin
      xyz="0 0.03048 -0.14732"
      rpy="0 0 0" />
    <parent
      link="support_left" />
    <child
      link="front_left_wheel" />
    <axis
      xyz="0 -1 0" />
    <limit
      effort="30"
      velocity="100" />
  </joint>
  <link
    name="support_right">
    <inertial>
      <origin
        xyz="1.11022302462516E-16 -0.000175745860538229 -0.0988551027510242"
        rpy="0 0 0" />
      <mass
        value="0.511568168116718" />
      <inertia
        ixx="0.00233331327511673"
        ixy="4.81627040448131E-20"
        ixz="1.53131066763964E-18"
        iyy="0.00169516860077224"
        iyz="-7.37347093187839E-06"
        izz="0.00113414228037387" />
    </inertial>
    <visual>
      <origin
        xyz="0 0 0"
        rpy="0 0 0" />
      <geometry>
        <mesh
          filename="package://robot_urdf/meshes/support_right.STL" />
      </geometry>
      <material
        name="">
        <color
          rgba="0.898039215686275 0.917647058823529 0.929411764705882 1" />
      </material>
    </visual>
    <collision>
      <origin
        xyz="0 0 0"
        rpy="0 0 0" />
      <geometry>
        <mesh
          filename="package://robot_urdf/meshes/support_right.STL" />
      </geometry>
    </collision>
  </link>
  <joint
    name="j_support_right"
    type="revolute">
    <origin
      xyz="0.3683 -0.15113 0.24943"
      rpy="0 0 0" />
    <parent
      link="base_link" />
    <child
      link="support_right" />
    <axis
      xyz="0 0 1" />
    <limit
      lower="-1.0472"
      upper="1.0472"
      effort="10"
      velocity="100" />
  </joint>
  <link
    name="front_right_wheel">
    <inertial>
      <origin
        xyz="-1.11022302462516E-16 0.0272681474371539 4.16333634234434E-17"
        rpy="0 0 0" />
      <mass
        value="0.737916384214473" />
      <inertia
        ixx="0.00279813808464155"
        ixy="6.71133983372056E-19"
        ixz="2.82564897248114E-18"
        iyy="0.00513458608151511"
        iyz="-1.02883637816587E-18"
        izz="0.00279813808464154" />
    </inertial>
    <visual>
      <origin
        xyz="0 0 0"
        rpy="0 0 0" />
      <geometry>
        <mesh
          filename="package://robot_urdf/meshes/front_right_wheel.STL" />
      </geometry>
      <material
        name="">
        <color
          rgba="0.792156862745098 0.819607843137255 0.933333333333333 1" />
      </material>
    </visual>
    <collision>
      <origin
        xyz="0 0 0"
        rpy="0 0 0" />
      <geometry>
        <mesh
          filename="package://robot_urdf/meshes/front_right_wheel.STL" />
      </geometry>
    </collision>
  </link>
  <joint
    name="j_front_right_wheel"
    type="continuous">
    <origin
      xyz="0 -0.03048 -0.14732"
      rpy="0 0 0" />
    <parent
      link="support_right" />
    <child
      link="front_right_wheel" />
    <axis
      xyz="0 -1 0" />
    <limit
      effort="30"
      velocity="100" />
  </joint>
  <link
    name="rear_left_wheel">
    <inertial>
      <origin
        xyz="-5.55111512312578E-17 -0.0272681474371538 2.77555756156289E-17"
        rpy="0 0 0" />
      <mass
        value="0.737916384214473" />
      <inertia
        ixx="0.00279813808464154"
        ixy="1.11590459934088E-19"
        ixz="-2.45201083392975E-18"
        iyy="0.0051345860815151"
        iyz="1.67351097464878E-19"
        izz="0.00279813808464155" />
    </inertial>
    <visual>
      <origin
        xyz="0 0 0"
        rpy="0 0 0" />
      <geometry>
        <mesh
          filename="package://robot_urdf/meshes/rear_left_wheel.STL" />
      </geometry>
      <material
        name="">
        <color
          rgba="0.792156862745098 0.819607843137255 0.933333333333333 1" />
      </material>
    </visual>
    <collision>
      <origin
        xyz="0 0 0"
        rpy="0 0 0" />
      <geometry>
        <mesh
          filename="package://robot_urdf/meshes/rear_left_wheel.STL" />
      </geometry>
    </collision>
  </link>
  <joint
    name="j_rear_left_wheel"
    type="continuous">
    <origin
      xyz="-0.381 0.18161 0.10211"
      rpy="0 0 0" />
    <parent
      link="base_link" />
    <child
      link="rear_left_wheel" />
    <axis
      xyz="0 -1 0" />
    <limit
      effort="30"
      velocity="100" />
  </joint>
  <link
    name="rear_right_wheel">
    <inertial>
      <origin
        xyz="-1.11022302462516E-16 0.0336918525628461 -2.77555756156289E-17"
        rpy="0 0 0" />
      <mass
        value="0.737916384214473" />
      <inertia
        ixx="0.00279813808464154"
        ixy="-4.92403285766757E-19"
        ixz="-1.01956744195369E-18"
        iyy="0.0051345860815151"
        iyz="3.79673346254853E-20"
        izz="0.00279813808464154" />
    </inertial>
    <visual>
      <origin
        xyz="0 0 0"
        rpy="0 0 0" />
      <geometry>
        <mesh
          filename="package://robot_urdf/meshes/rear_right_wheel.STL" />
      </geometry>
      <material
        name="">
        <color
          rgba="0.792156862745098 0.819607843137255 0.933333333333333 1" />
      </material>
    </visual>
    <collision>
      <origin
        xyz="0 0 0"
        rpy="0 0 0" />
      <geometry>
        <mesh
          filename="package://robot_urdf/meshes/rear_right_wheel.STL" />
      </geometry>
    </collision>
  </link>
  <joint
    name="j_rear_right_wheel"
    type="continuous">
    <origin
      xyz="-0.381 -0.18161 0.10211"
      rpy="0 0 0" />
    <parent
      link="base_link" />
    <child
      link="rear_right_wheel" />
    <axis
      xyz="0 -1 0" />
    <limit
      effort="30"
      velocity="100" />
  </joint>
</robot>