<?xml version="1.0" encoding="utf-8"?>
<!-- This URDF was automatically created by SolidWorks to URDF Exporter! Originally created by Stephen Brawner (brawner@gmail.com) 
     Commit Version: 1.6.0-4-g7f85cfe  Build Version: 1.6.7995.38578
     For more information, please see http://wiki.ros.org/sw_urdf_exporter -->
<robot
  name="robot_urdf">
  <link
    name="base_link">
    <inertial>
      <origin
        xyz="0.00572008565715467 -0.0179961004649497 1.73194173166296E-06"
        rpy="0 0 0" />
      <mass
        value="50.9630293132178" />
      <inertia
        ixx="1.10817698910646"
        ixy="-0.0198174312915715"
        ixz="4.08596400870225E-05"
        iyy="5.0811926943117"
        iyz="-1.90741069630568E-08"
        izz="3.99708985218424" />
    </inertial>
    <visual>
      <origin
        xyz="0 0 0"
        rpy="0 0 0" />
      <geometry>
        <mesh
          filename="package://robot_urdf/meshes/base_link.STL" />
      </geometry>
      <material
        name="">
        <color
          rgba="0.898039215686275 0.917647058823529 0.929411764705882 1" />
      </material>
    </visual>
    <collision>
      <origin
        xyz="0 0 0"
        rpy="0 0 0" />
      <geometry>
        <mesh
          filename="package://robot_urdf/meshes/base_link.STL" />
      </geometry>
    </collision>
  </link>
  <link
    name="rear_left_wheel">
    <inertial>
      <origin
        xyz="0.368300000000054 -0.151129999998913 -0.160020000000019"
        rpy="0 0 0" />
      <mass
        value="5.71507847538442" />
      <inertia
        ixx="0.0206714901188206"
        ixy="4.77565279722644E-15"
        ixz="-3.35524546891118E-13"
        iyy="0.0379211813475922"
        iyz="-3.58028205423057E-15"
        izz="0.0206714901183378" />
    </inertial>
    <visual>
      <origin
        xyz="0 0 0"
        rpy="0 0 0" />
      <geometry>
        <mesh
          filename="package://robot_urdf/meshes/rear_left_wheel.STL" />
      </geometry>
      <material
        name="">
        <color
          rgba="0.898039215686275 0.917647058823529 0.929411764705882 1" />
      </material>
    </visual>
    <collision>
      <origin
        xyz="0 0 0"
        rpy="0 0 0" />
      <geometry>
        <mesh
          filename="package://robot_urdf/meshes/rear_left_wheel.STL" />
      </geometry>
    </collision>
  </link>
  <joint
    name="j_rear_left_wheel"
    type="revolute">
    <origin
      xyz="0 -0.0381 0"
      rpy="1.5708 0 0" />
    <parent
      link="base_link" />
    <child
      link="rear_left_wheel" />
    <axis
      xyz="0 1 0" />
    <limit
      lower="0"
      upper="0"
      effort="0"
      velocity="0" />
  </joint>
  <link
    name="rear_right_wheel">
    <inertial>
      <origin
        xyz="0.368299999999975 0.15112999999891 -0.160019999999946"
        rpy="0 0 0" />
      <mass
        value="5.71507847538443" />
      <inertia
        ixx="0.0206714901184329"
        ixy="5.04361647178062E-15"
        ixz="-3.86343563255688E-13"
        iyy="0.0379211813475922"
        iyz="-5.46945819816413E-15"
        izz="0.0206714901187268" />
    </inertial>
    <visual>
      <origin
        xyz="0 0 0"
        rpy="0 0 0" />
      <geometry>
        <mesh
          filename="package://robot_urdf/meshes/rear_right_wheel.STL" />
      </geometry>
      <material
        name="">
        <color
          rgba="0.898039215686275 0.917647058823529 0.929411764705882 1" />
      </material>
    </visual>
    <collision>
      <origin
        xyz="0 0 0"
        rpy="0 0 0" />
      <geometry>
        <mesh
          filename="package://robot_urdf/meshes/rear_right_wheel.STL" />
      </geometry>
    </collision>
  </link>
  <joint
    name="j_rear_right_wheel"
    type="revolute">
    <origin
      xyz="0 -0.0381 0"
      rpy="1.5708 0 0" />
    <parent
      link="base_link" />
    <child
      link="rear_right_wheel" />
    <axis
      xyz="0 1 0" />
    <limit
      lower="0"
      upper="0"
      effort="0"
      velocity="0" />
  </joint>
  <link
    name="front_left_chassis">
    <inertial>
      <origin
        xyz="-0.368393558683625 -0.152678307431702 -0.0894006385266943"
        rpy="0 0 0" />
      <mass
        value="0.141762199312227" />
      <inertia
        ixx="0.000656933169628175"
        ixy="-3.37622475088239E-05"
        ixz="-1.34543576490875E-06"
        iyy="0.000567851047509447"
        iyz="-4.00224498402914E-06"
        izz="0.000441916567523272" />
    </inertial>
    <visual>
      <origin
        xyz="0 0 0"
        rpy="0 0 0" />
      <geometry>
        <mesh
          filename="package://robot_urdf/meshes/front_left_chassis.STL" />
      </geometry>
      <material
        name="">
        <color
          rgba="0.792156862745098 0.819607843137255 0.933333333333333 1" />
      </material>
    </visual>
    <collision>
      <origin
        xyz="0 0 0"
        rpy="0 0 0" />
      <geometry>
        <mesh
          filename="package://robot_urdf/meshes/front_left_chassis.STL" />
      </geometry>
    </collision>
  </link>
  <joint
    name="j_front_left_chassis"
    type="revolute">
    <origin
      xyz="0 -0.0381 0"
      rpy="1.5708 0 0" />
    <parent
      link="base_link" />
    <child
      link="front_left_chassis" />
    <axis
      xyz="0 0 1" />
    <limit
      lower="0"
      upper="0"
      effort="0"
      velocity="0" />
  </joint>
  <link
    name="front_left_wheel">
    <inertial>
      <origin
        xyz="-0.36829999999966 -0.152399999998963 -0.160019999999948"
        rpy="0 0 0" />
      <mass
        value="5.71507847538441" />
      <inertia
        ixx="0.0224229519698563"
        ixy="0.00521004390805073"
        ixz="3.64748422798132E-14"
        iyy="0.0361697194959044"
        iyz="-4.27011704060522E-15"
        izz="0.0206714901189918" />
    </inertial>
    <visual>
      <origin
        xyz="0 0 0"
        rpy="0 0 0" />
      <geometry>
        <mesh
          filename="package://robot_urdf/meshes/front_left_wheel.STL" />
      </geometry>
      <material
        name="">
        <color
          rgba="0.898039215686275 0.917647058823529 0.929411764705882 1" />
      </material>
    </visual>
    <collision>
      <origin
        xyz="0 0 0"
        rpy="0 0 0" />
      <geometry>
        <mesh
          filename="package://robot_urdf/meshes/front_left_wheel.STL" />
      </geometry>
    </collision>
  </link>
  <joint
    name="j_front_left_wheel"
    type="revolute">
    <origin
      xyz="0 0 0"
      rpy="0 0 0" />
    <parent
      link="front_left_chassis" />
    <child
      link="front_left_wheel" />
    <axis
      xyz="-0.318646885836196 -0.947873494801334 0" />
    <limit
      lower="0"
      upper="0"
      effort="0"
      velocity="0" />
  </joint>
  <link
    name="front_right_chassis">
    <inertial>
      <origin
        xyz="-0.368194892126035 0.152125845684597 -0.0894006385266943"
        rpy="0 0 0" />
      <mass
        value="0.141762199312227" />
      <inertia
        ixx="0.000653958088941888"
        ixy="3.7363949908515E-05"
        ixz="1.5115207624209E-06"
        iyy="0.000570826128195732"
        iyz="-3.94252042410051E-06"
        izz="0.000441916567523272" />
    </inertial>
    <visual>
      <origin
        xyz="0 0 0"
        rpy="0 0 0" />
      <geometry>
        <mesh
          filename="package://robot_urdf/meshes/front_right_chassis.STL" />
      </geometry>
      <material
        name="">
        <color
          rgba="0.792156862745098 0.819607843137255 0.933333333333333 1" />
      </material>
    </visual>
    <collision>
      <origin
        xyz="0 0 0"
        rpy="0 0 0" />
      <geometry>
        <mesh
          filename="package://robot_urdf/meshes/front_right_chassis.STL" />
      </geometry>
    </collision>
  </link>
  <joint
    name="j_front_right_chassis"
    type="revolute">
    <origin
      xyz="0 -0.0381 0"
      rpy="1.5707963267949 0 0" />
    <parent
      link="base_link" />
    <child
      link="front_right_chassis" />
    <axis
      xyz="0 0 1" />
    <limit
      lower="0"
      upper="0"
      effort="0"
      velocity="0" />
  </joint>
  <link
    name="front_right_wheel">
    <inertial>
      <origin
        xyz="-0.36830000000044 0.152400000001002 -0.160020000000008"
        rpy="0 0 0" />
      <mass
        value="5.71507847538429" />
      <inertia
        ixx="0.0228820535455402"
        ixy="-0.00576584303345054"
        ixz="-1.83225312336562E-14"
        iyy="0.035710617921044"
        iyz="-5.29024496679622E-15"
        izz="0.0206714901181666" />
    </inertial>
    <visual>
      <origin
        xyz="0 0 0"
        rpy="0 0 0" />
      <geometry>
        <mesh
          filename="package://robot_urdf/meshes/front_right_wheel.STL" />
      </geometry>
      <material
        name="">
        <color
          rgba="0.898039215686275 0.917647058823529 0.929411764705882 1" />
      </material>
    </visual>
    <collision>
      <origin
        xyz="0 0 0"
        rpy="0 0 0" />
      <geometry>
        <mesh
          filename="package://robot_urdf/meshes/front_right_wheel.STL" />
      </geometry>
    </collision>
  </link>
  <joint
    name="j_front_right_wheel"
    type="continuous">
    <origin
      xyz="0 0 0"
      rpy="0 0 0" />
    <parent
      link="front_right_chassis" />
    <child
      link="front_right_wheel" />
    <axis
      xyz="0.357981701084848 -0.93372860172986 0" />
  </joint>
</robot>